<?xml version="1.0"?>
<robot name="aubo_i16_gripper">

  <link name="base_link">
    <inertial>
      <origin xyz="0.0 0.0028308 0.022423" rpy="0 0 0" />
      <mass value="1.3804" />
      <inertia ixx="0.0037534" ixy="0.0" ixz="0.0" iyy="0.0033643" iyz="0.0" izz="0.0064603" />
    </inertial>
    <visual>
      <origin xyz="0 0 0" rpy="0 0 0" />
      <geometry>
        <mesh filename="meshes/aubo_i16/visual/base_Link.DAE" />
      </geometry>
      <material name="">
        <color rgba="1 1 1 1" />
      </material>
    </visual>
    <collision>
      <origin xyz="0 0 0" rpy="0 0 0" />
      <geometry>
        <mesh filename="meshes/aubo_i16/collision/base_Link.STL" />
      </geometry>
    </collision>
  </link>

  <link name="shoulder_Link">
    <inertial>
      <origin xyz="0.0 0.12677 0.28186" rpy="0 0 0" />
      <mass value="7.1699" />
      <inertia ixx="0.63338" ixy="0.0" ixz="0.0" iyy="0.58429" iyz="-0.043514" izz="0.063992" />
    </inertial>
    <visual>
      <origin xyz="0 0 0" rpy="0 0 0" />
      <geometry>
        <mesh filename="meshes/aubo_i16/visual/shoulder_Link.DAE" />
      </geometry>
      <material name="">
        <color rgba="1 1 1 1" />
      </material>
    </visual>
    <collision>
      <origin xyz="0 0 0" rpy="0 0 0" />
      <geometry>
        <mesh filename="meshes/aubo_i16/collision/shoulder_Link.STL" />
      </geometry>
    </collision>
  </link>

  <joint name="shoulder_joint" type="revolute">
    <origin xyz="0 0 0.163" rpy="0 0 3.1416" />
    <parent link="base_link" />
    <child link="shoulder_Link" />
    <axis xyz="0 0 1" />
    <limit lower="-6.5" upper="6.5" effort="0" velocity="0" />
  </joint>

  <link name="upperArm_Link">
    <inertial>
      <origin xyz="0.243589520699327 0.0 0.00600111824205077" rpy="0 0 0" />
      <mass value="3.70827585534885" />
      <inertia ixx="0.00681728559415309" ixy="0.0" ixz="0.0" iyy="0.0397176571714556" iyz="0.0" izz="0.0397173271934915" />
    </inertial>
    <visual>
      <origin xyz="0 0 0" rpy="0 0 0" />
      <geometry>
        <mesh filename="meshes/aubo_i16/visual/upperArm_Link.DAE" />
      </geometry>
      <material name="">
        <color rgba="1 1 1 1" />
      </material>
    </visual>
    <collision>
      <origin xyz="0 0 0" rpy="0 0 0" />
      <geometry>
        <mesh filename="meshes/aubo_i16/collision/upperArm_Link.STL" />
      </geometry>
    </collision>
  </link>

  <joint name="upperArm_joint" type="revolute">
    <origin xyz="0 0.191 0" rpy="-1.5708 -1.5708 0" />
    <parent link="shoulder_Link" />
    <child link="upperArm_Link" />
    <axis xyz="0 0 1" />
    <limit lower="-6.5" upper="6.5" effort="0" velocity="0" />
  </joint>

  <link name="foreArm_Link">
    <inertial>
      <origin xyz="0.13154 0.0 0.11387" rpy="0 0 0" />
      <mass value="1.9726" />
      <inertia ixx="0.001838" ixy="0.0" ixz="-0.00099364" iyy="0.023606" iyz="0.0" izz="0.023656" />
    </inertial>
    <visual>
      <origin xyz="0 0 0" rpy="0 0 0" />
      <geometry>
        <mesh filename="meshes/aubo_i16/visual/foreArm_Link.DAE" />
      </geometry>
      <material name="">
        <color rgba="1 1 1 1" />
      </material>
    </visual>
    <collision>
      <origin xyz="0 0 0" rpy="0 0 0" />
      <geometry>
        <mesh filename="meshes/aubo_i16/collision/foreArm_Link.STL" />
      </geometry>
    </collision>
  </link>

  <joint name="foreArm_joint" type="revolute">
    <origin xyz="0.48008 0 0" rpy="-3.1416 0 0" />
    <parent link="upperArm_Link" />
    <child link="foreArm_Link" />
    <axis xyz="0 0 1" />
    <limit lower="-6.5" upper="6.5" effort="0" velocity="0" />
  </joint>

  <link name="wrist1_Link">
    <inertial>
      <origin xyz="0.0 -0.56814 -0.064233" rpy="0 0 0" />
      <mass value="7.1699" />
      <inertia ixx="0.63338" ixy="0.0" ixz="0.0" iyy="0.063992" iyz="-0.043514" izz="0.58429" />
    </inertial>
    <visual>
      <origin xyz="0 0 0" rpy="0 0 0" />
      <geometry>
        <mesh filename="meshes/aubo_i16/visual/wrist1_Link.DAE" />
      </geometry>
      <material name="">
        <color rgba="1 1 1 1" />
      </material>
    </visual>
    <collision>
      <origin xyz="0 0 0" rpy="0 0 0" />
      <geometry>
        <mesh filename="meshes/aubo_i16/collision/wrist1_Link.STL" />
      </geometry>
    </collision>
  </link>

  <joint name="wrist1_joint" type="revolute">
    <origin xyz="0.36992 0 0" rpy="3.1416 0 1.5708" />
    <parent link="foreArm_Link" />
    <child link="wrist1_Link" />
    <axis xyz="0 0 1" />
    <limit lower="-6.5" upper="6.5" effort="0" velocity="0" />
  </joint>

  <link name="wrist2_Link">
    <inertial>
      <origin xyz="0.0 0.064233 -0.68564" rpy="0 0 0" />
      <mass value="7.1699" />
      <inertia ixx="0.63338" ixy="0.0" ixz="0.0" iyy="0.58429" iyz="0.043514" izz="0.063992" />
    </inertial>
    <visual>
      <origin xyz="0 0 0" rpy="0 0 0" />
      <geometry>
        <mesh filename="meshes/aubo_i16/visual/wrist2_Link.DAE" />
      </geometry>
      <material name="">
        <color rgba="1 1 1 1" />
      </material>
    </visual>
    <collision>
      <origin xyz="0 0 0" rpy="0 0 0" />
      <geometry>
        <mesh filename="meshes/aubo_i16/collision/wrist2_Link.STL" />
      </geometry>
    </collision>
  </link>

  <joint name="wrist2_joint" type="revolute">
    <origin xyz="0 0.1175 0" rpy="-1.5708 0 0" />
    <parent link="wrist1_Link" />
    <child link="wrist2_Link" />
    <axis xyz="0 0 1" />
    <limit lower="-6.5" upper="6.5" effort="0" velocity="0" />
  </joint>

  <link name="wrist3_Link">
    <inertial>
      <origin xyz="0.0 0.00054964 -0.017144" rpy="0 0 0" />
      <mass value="0.10863" />
      <inertia ixx="0.0" ixy="0.0" ixz="0.0" iyy="0.0" iyz="0.0" izz="0.00013551" />
    </inertial>
    <visual>
      <origin xyz="0 0 0" rpy="0 0 0" />
      <geometry>
        <mesh filename="meshes/aubo_i16/visual/wrist3_Link.DAE" />
      </geometry>
      <material name="">
        <color rgba="1 1 1 1" />
      </material>
    </visual>
    <collision>
      <origin xyz="0 0 0" rpy="0 0 0" />
      <geometry>
        <mesh filename="meshes/aubo_i16/collision/wrist3_Link.STL" />
      </geometry>
    </collision>
  </link>

  <joint name="wrist3_joint" type="revolute">
    <origin xyz="0 -0.1035 0" rpy="1.5708 0 0" />
    <parent link="wrist2_Link" />
    <child link="wrist3_Link" />
    <axis xyz="0 0 1" />
    <limit lower="-6.5" upper="6.5" effort="0" velocity="0" />
  </joint>

  <joint name="gripper_base_joint" type="fixed">
    <parent link="wrist3_Link" />
    <child link="gripper_base_link" />
    <origin xyz="0 0 0" rpy="0 0 0" />
  </joint>

  <link name="gripper_base_link">
    <inertial>
      <origin xyz="0.000776249315939448 -9.32733579416881E-05 0.0353238890747118" rpy="0 0 0" />
      <mass value="0.175159784385337" />
      <inertia ixx="8.17697339684563E-05" ixy="-3.45127488505508E-09" ixz="-1.78295110539977E-06" iyy="0.000167947939418876" iyz="-4.09263769978131E-08" izz="0.000222515998258674" />
    </inertial>
    <visual>
      <origin xyz="0 0 0" rpy="0 0 0" />
      <geometry>
        <mesh filename="meshes/gripper/base_link.STL" />
      </geometry>
      <material name="">
        <color rgba="0.792156862745098 0.819607843137255 0.933333333333333 1" />
      </material>
    </visual>
    <collision>
      <origin xyz="0 0 0" rpy="0 0 0" />
      <geometry>
        <mesh filename="meshes/gripper/base_link.STL" />
      </geometry>
    </collision>
  </link>

  <link name="left_link">
    <inertial>
      <origin xyz="0.037632 -0.0088006 0.00096534" rpy="0 0 0" />
      <mass value="0.055911" />
      <inertia ixx="1.8833E-05" ixy="4.3686E-06" ixz="-4.9039E-06" iyy="3.1447E-05" iyz="3.7712E-06" izz="2.217E-05" />
    </inertial>
    <visual>
      <origin xyz="0 0 0" rpy="0 0 0" />
      <geometry>
        <mesh filename="meshes/gripper/left_link.STL" />
      </geometry>
      <material name="">
        <color rgba="0.79216 0.81961 0.93333 1" />
      </material>
    </visual>
    <collision>
      <origin xyz="0 0 0" rpy="0 0 0" />
      <geometry>
        <mesh filename="meshes/gripper/left_link.STL" />
      </geometry>
    </collision>
  </link>

  <joint name="left_joint" type="prismatic">
    <origin xyz="-0.04 0 0.14124" rpy="0 1.5708 0" />
    <parent link="gripper_base_link" />
    <child link="left_link" />
    <axis xyz="0 0 -1" />
    <limit lower="-0.04" upper="0" effort="100" velocity="1" />
  </joint>

  <link name="right_link">
    <inertial>
      <origin xyz="-0.037632201993843 0.00880061259646711 0.000965336223160473" rpy="0 0 0" />
      <mass value="0.0559111685912142" />
      <inertia ixx="1.88326524562505E-05" ixy="4.36861035916738E-06" ixz="4.90389857081758E-06" iyy="3.1447169883483E-05" iyz="-3.77124422603238E-06" izz="2.21699046566701E-05" />
    </inertial>
    <visual>
      <origin xyz="0 0 0" rpy="0 0 0" />
      <geometry>
        <mesh filename="meshes/gripper/right_link.STL" />
      </geometry>
      <material name="">
        <color rgba="0.792156862745098 0.819607843137255 0.933333333333333 1" />
      </material>
    </visual>
    <collision>
      <origin xyz="0 0 0" rpy="0 0 0" />
      <geometry>
        <mesh filename="meshes/gripper/right_link.STL" />
      </geometry>
    </collision>
  </link>

  <joint name="right_joint" type="prismatic">
    <origin xyz="0.04 0 0.14124" rpy="0 -1.5708 0" />
    <parent link="gripper_base_link" />
    <child link="right_link" />
    <axis xyz="0 0 -1" />
    <limit lower="-0.04" upper="0" effort="100" velocity="1" />
  </joint>

  <link name="world" />

  <joint name="world_joint" type="fixed">
    <parent link="world" />
    <child link="base_link" />
    <origin xyz="0.0 0.0 0.0" rpy="0.0 0.0 0.0" />
  </joint>

</robot>
